<?xml version="1.0"?>
<robot name="zx200" xmlns:xacro="http://www.ros.org/wiki/xacro">

	<!-- Import all Gazebo-customization elements, including Gazebo colors -->
	<!-- <xacro:include filename="$(find zx200_description)/urdf/zx200.gazebo" /> -->
	<!-- Import Rviz colors -->
	<!-- <xacro:include filename="$(find zx200_description)/urdf/materials.xacro" /> -->

	<!-- Used for fixing robot to Gazebo 'base_link' -->
	<link name="base_link"/>

	<joint name="base_joint" type="fixed">
		<parent link="base_link"/>
		<child link="track_link"/>
	</joint>

	<!-- Base Link -->
	<link name="track_link">
		<visual>
			<geometry>
				<mesh filename="package://zx200_description/meshes/zx200-crawler.dae"/>
			</geometry>
		</visual>

		<collision>
			<geometry>
				<mesh filename="package://zx200_description/meshes/zx200-crawler.dae"/>
			</geometry>
		</collision>

		<inertial>
			<origin xyz="0 0 0" rpy="0 0 0"/>
			<mass value="0.03"/>
			<inertia ixx="1.0" ixy="0.0" ixz="0.0"
								iyy="1.0" iyz="0.0"
											izz="1.0"/>
		</inertial>
	</link>

	<!-- body axis -->
	<joint name="swing_joint" type="continuous">
		<origin xyz="0.10787 -0.034301 1.1206"/>
		<axis xyz="0 0 1"/>
		<parent link="track_link"/>
		<child link="body_link"/>
	</joint>

	<link name="body_link">
		<visual>
			<origin xyz="0 0 0"/>
			<geometry>
				<mesh filename="package://zx200_description/meshes/zx200-body.dae"/>
			</geometry>
		</visual>

		<collision>
			<origin xyz="0 0 0"/>
			<geometry>
				<mesh filename="package://zx200_description/meshes/zx200-body.dae"/>
			</geometry>
		</collision>

		<inertial>
			<origin xyz="0 0 0" rpy="0 0 0"/>
			<mass value="0.03"/>
			<inertia ixx="1.0" ixy="0.0" ixz="0.0"
								iyy="1.0" iyz="0.0"
											izz="1.0"/>
		</inertial>
	</link>

	<!-- boom axis -->
	<joint name="boom_joint" type="revolute">
		<origin xyz="0.22767 -0.040187 0.83669"/>
		<axis xyz="0 1 0"/>
		<parent link="body_link"/>
		<child link="boom_link"/>
		<limit lower="${radians(-20)}" upper="${radians(55)}" effort="500" velocity="6.159937255"/>
	</joint>


	<link name="boom_link">
		<visual>
			<origin xyz="0 0 0"/>
			<geometry>
				<mesh filename="package://zx200_description/meshes/zx200-boom.dae"/>
			</geometry>
		</visual>

		<collision>
			<origin xyz="0 0 0"/>
			<geometry>
				<mesh filename="package://zx200_description/meshes/zx200-boom.dae"/>
			</geometry>
		</collision>

		<inertial>
			<origin xyz="0 0 0" rpy="0 0 0"/>
			<mass value="0.03"/>
			<inertia ixx="1.0" ixy="0.0" ixz="0.0"
								iyy="1.0" iyz="0.0"
											izz="1.0"/>
		</inertial>
	</link>

	<joint name="arm_joint" type="revolute">
		<origin xyz="4.7878 0.010957 2.9959"/>
		<axis xyz="0 1 0"/>
		<parent link="boom_link"/>
		<child link="arm_link"/>
		<limit lower="${radians(45)}" upper="${radians(145)}" effort="500" velocity="6.159937255"/>
	</joint>

	<link name="arm_link">
		<visual>
			<origin xyz="0 0 0"/>
			<geometry>
				<mesh filename="package://zx200_description/meshes/zx200-arm.dae"/>
			</geometry>
		</visual>

		<collision>
			<origin xyz="0 0 0"/>
			<geometry>
				<mesh filename="package://zx200_description/meshes/zx200-arm.dae"/>
			</geometry>
		</collision>

		<inertial>
			<origin xyz="0 0 0" rpy="0 0 0"/>
			<mass value="0.03"/>
			<inertia ixx="1.0" ixy="0.0" ixz="0.0"
								iyy="1.0" iyz="0.0"
											izz="1.0"/>
		</inertial>
	</link>

	<!-- bucket axis -->
	<joint name="bucket_joint" type="revolute">
		<origin xyz="1.8954 -0.023546 2.1809"/>
		<axis xyz="0 1 0"/>
		<parent link="arm_link"/>
		<child link="bucket_link"/>
		<limit lower="${radians(-70)}" upper="${radians(80)}" effort="500" velocity="6.159937255"/>
	</joint>

	<link name="bucket_link">
		<visual>
			<origin xyz="0 0 0"/>
			<geometry>
				<mesh filename="package://zx200_description/meshes/zx200-bucket.dae"/>
			</geometry>
		</visual>

		<collision>
			<origin xyz="0 0 0"/>
			<geometry>
				<mesh filename="package://zx200_description/meshes/zx200-bucket.dae"/>
			</geometry>
		</collision>

		<inertial>
			<origin xyz="0 0 0" rpy="0 0 0"/>
			<mass value="0.03"/>
			<inertia ixx="1.0" ixy="0.0" ixz="0.0"
								iyy="1.0" iyz="0.0"
											izz="1.0"/>
		</inertial>
	</link>

	<link name="bucket_end_link">
		<visual>
			<origin xyz="0 0 0" rpy="0 0 0"/>
			<geometry>
				<box size="0.001 0.001 0.001" />
			</geometry>
			<!-- <material name="red"/> -->
		</visual>
		<inertial>
			<origin xyz="0 0 0" />
			<mass value="1.0e-03" />
			<inertia ixx="1.0e-03" ixy="0.0" ixz="0.0"
					iyy="1.0e-03" iyz="0.0"
					izz="1.0e-03" />
		</inertial>
  	</link>

  <joint name="bucket_end_joint" type="revolute">
    <parent link="bucket_link"/>
    <child link="bucket_end_link"/>
    <axis xyz="1 0 0"/>
    <origin rpy="0 ${radians(50)} 0" xyz="0 0 1.23"/>
    <limit effort="1" lower="-3.14" upper="3.14" velocity="0.5"/>
  </joint>

	<transmission name="tran1">
		<type>transmission_interface/SimpleTransmission</type>
		<joint name="swing_joint">
			<hardwareInterface>hardware_interface/EffortJointInterface</hardwareInterface>
		</joint>
		<actuator name="motor1">
			<hardwareInterface>hardware_interface/EffortJointInterface</hardwareInterface>
			<mechanicalReduction>1</mechanicalReduction>
		</actuator>
	</transmission>

	<transmission name="tran2">
		<type>transmission_interface/SimpleTransmission</type>
		<joint name="boom_joint">
			<hardwareInterface>hardware_interface/EffortJointInterface</hardwareInterface>
		</joint>
		<actuator name="motor2">
			<hardwareInterface>hardware_interface/EffortJointInterface</hardwareInterface>
			<mechanicalReduction>1</mechanicalReduction>
		</actuator>
	</transmission>

	<transmission name="tran3">
		<type>transmission_interface/SimpleTransmission</type>
		<joint name="arm_joint">
			<hardwareInterface>hardware_interface/EffortJointInterface</hardwareInterface>
		</joint>
		<actuator name="motor3">
			<hardwareInterface>hardware_interface/EffortJointInterface</hardwareInterface>
			<mechanicalReduction>1</mechanicalReduction>
		</actuator>
	</transmission>

	<transmission name="tran4">
		<type>transmission_interface/SimpleTransmission</type>
		<joint name="bucket_joint">
			<hardwareInterface>hardware_interface/EffortJointInterface</hardwareInterface>
		</joint>
		<actuator name="motor4">
			<hardwareInterface>hardware_interface/EffortJointInterface</hardwareInterface>
			<mechanicalReduction>1</mechanicalReduction>
		</actuator>
	</transmission>

</robot>
